/data/home1/ssahoo/miniconda3/envs/kgconv2/bin/python: can't open file 'train.py': [Errno 2] No such file or directory
/data/home1/ssahoo/miniconda3/envs/kgconv2/lib/python3.7/site-packages/torch/distributed/launch.py:186: FutureWarning: The module torch.distributed.launch is deprecated
and will be removed in future. Use torchrun.
Note that --use_env is set by default in torchrun.
If your script expects `--local_rank` argument to be set, please
change it to read from `os.environ['LOCAL_RANK']` instead. See 
https://pytorch.org/docs/stable/distributed.html#launch-utility for 
further instructions

  FutureWarning,
ERROR:torch.distributed.elastic.multiprocessing.api:failed (exitcode: 2) local_rank: 0 (pid: 18249) of binary: /data/home1/ssahoo/miniconda3/envs/kgconv2/bin/python
Traceback (most recent call last):
  File "/data/home1/ssahoo/miniconda3/envs/kgconv2/lib/python3.7/runpy.py", line 193, in _run_module_as_main
    "__main__", mod_spec)
  File "/data/home1/ssahoo/miniconda3/envs/kgconv2/lib/python3.7/runpy.py", line 85, in _run_code
    exec(code, run_globals)
  File "/data/home1/ssahoo/miniconda3/envs/kgconv2/lib/python3.7/site-packages/torch/distributed/launch.py", line 193, in <module>
    main()
  File "/data/home1/ssahoo/miniconda3/envs/kgconv2/lib/python3.7/site-packages/torch/distributed/launch.py", line 189, in main
    launch(args)
  File "/data/home1/ssahoo/miniconda3/envs/kgconv2/lib/python3.7/site-packages/torch/distributed/launch.py", line 174, in launch
    run(args)
  File "/data/home1/ssahoo/miniconda3/envs/kgconv2/lib/python3.7/site-packages/torch/distributed/run.py", line 713, in run
    )(*cmd_args)
  File "/data/home1/ssahoo/miniconda3/envs/kgconv2/lib/python3.7/site-packages/torch/distributed/launcher/api.py", line 131, in __call__
    return launch_agent(self._config, self._entrypoint, list(args))
  File "/data/home1/ssahoo/miniconda3/envs/kgconv2/lib/python3.7/site-packages/torch/distributed/launcher/api.py", line 261, in launch_agent
    failures=result.failures,
torch.distributed.elastic.multiprocessing.errors.ChildFailedError: 
============================================================
train.py FAILED
------------------------------------------------------------
Failures:
  <NO_OTHER_FAILURES>
------------------------------------------------------------
Root Cause (first observed failure):
[0]:
  time      : 2022-06-01_20:23:45
  host      : eis-warpcore-01.iais.fraunhofer.de
  rank      : 0 (local_rank: 0)
  exitcode  : 2 (pid: 18249)
  error_file: <N/A>
  traceback : To enable traceback see: https://pytorch.org/docs/stable/elastic/errors.html
============================================================
